Workbook

Sheet 埋点数据
A1: 时间 | B1: event_type | C1: query | D1: desensitized_query | E1: intent | F1: confidence | G1: reason | H1: risk_type | I1: risk_reason | J1: conversation_id | K1: dialogue_count | L1: payload_json | M1: transfer_json | N1: badcase_json
A2: 46216.724 | B2: intent_classify | C2: T恤是什么材质的？ | D2: T恤是什么材质的？ | E2: 售前咨询 | F2: 0.98 | G2: 询问商品材质，属于购买前常见问题 | H2: 无 | I2: 正常咨询 | J2: fcf8d425-6db6-405e-baaf-2cf3735b295f | K2: 1
A3: 46216.724 | B3: intent_classify | C3: T恤是什么材质的？ | D3: T恤是什么材质的？ | E3: 售前咨询 | L3: {"event": "knowledge_search
A4: 46216.724 | B4: intent_classify | C4: T恤是什么材质的？ | D4: T恤是什么材质的？ | E4: 售前咨询 | L4: {"event": "answer_generate
A5: 46223.479 | B5: intent_classify | C5: 这件T恤是什么材质的 | D5: 这件T恤是什么材质的 | E5: 售前咨询 | F5: 0.98 | G5: 询问商品材质，属于购买前的问题 | H5: 无 | I5: 正常问题 | J5: 03255551-0fe4-4a96-9c25-cb0d8c6fe99a | K5: 1
A6: 46223.479 | B6: intent_classify | C6: 这件T恤是什么材质的 | D6: 这件T恤是什么材质的 | E6: 售前咨询 | L6: {"event": "knowledge_search
A7: 46223.479 | B7: intent_classify | C7: 这件T恤是什么材质的 | D7: 这件T恤是什么材质的 | E7: 售前咨询 | L7: {"event": "answer_generate
A8: 46223.479 | B8: intent_classify | C8: 有优惠吗 | D8: 有优惠吗 | E8: 售前咨询 | F8: 0.95 | G8: 询问优惠信息 | H8: 无 | I8: 正常咨询 | J8: 165c548a-134a-4eb4-aa72-79f78ecb4afa | K8: 1
A9: 46223.479 | B9: intent_classify | C9: 有优惠吗 | D9: 有优惠吗 | E9: 售前咨询 | L9: {"event": "knowledge_search
A10: 46223.479 | B10: intent_classify | C10: 有优惠吗 | D10: 有优惠吗 | E10: 售前咨询 | L10: {"event": "answer_generate
A11: 46223.479 | B11: intent_classify | C11: 我身高170体重120穿什么码 | D11: 我身高170体重120穿什么码 | E11: 售前咨询 | F11: 0.95 | G11: 询问适合的尺码，属于购买前商品信息咨询 | H11: 无 | I11: 正常尺码咨询 | J11: f9f44473-d48a-4947-ae2e-e7e3b6e3284d | K11: 1
A12: 46223.479 | B12: intent_classify | C12: 我身高170体重120穿什么码 | D12: 我身高170体重120穿什么码 | E12: 售前咨询 | L12: {"event": "knowledge_search
A13: 46223.479 | B13: intent_classify | C13: 我身高170体重120穿什么码 | D13: 我身高170体重120穿什么码 | E13: 售前咨询 | L13: {"event": "answer_generate
A14: 46223.479 | B14: intent_classify | C14: 白色会不会透 | D14: 白色会不会透 | E14: 售前咨询 | F14: 0.95 | G14: 询问商品颜色特性（白色是否透明），属于购买前商品信息咨询 | H14: 无 | I14: 正常问答 | J14: cdcdfe0a-64fe-429c-995e-26eaef612110 | K14: 1
A15: 46223.48 | B15: intent_classify | C15: 白色会不会透 | D15: 白色会不会透 | E15: 售前咨询 | L15: {"event": "knowledge_search
A16: 46223.48 | B16: intent_classify | C16: 白色会不会透 | D16: 白色会不会透 | E16: 售前咨询 | L16: {"event": "answer_generate
A17: 46223.48 | B17: intent_classify | C17: 这件T恤是什么材质的 | D17: 这件T恤是什么材质的 | E17: 售前咨询 | F17: 0.95 | G17: 询问商品材质 | H17: 无 | I17: 正常询问 | J17: ba0ac03b-9bf0-4124-ac26-37baf13bb6c5 | K17: 1
A18: 46223.48 | B18: intent_classify | C18: 牛仔裤有弹力吗 | D18: 牛仔裤有弹力吗 | E18: 售前咨询 | F18: 0.95 | G18: 询问商品功能（弹力） | H18: 无 | I18: 正常商品咨询 | J18: 5052743c-2e87-4667-b72c-bbd977dbf746 | K18: 1
A19: 46223.48 | B19: intent_classify | C19: 这件T恤是什么材质的 | D19: 这件T恤是什么材质的 | E19: 售前咨询 | L19: {"event": "knowledge_search
A20: 46223.48 | B20: intent_classify | C20: 牛仔裤有弹力吗 | D20: 牛仔裤有弹力吗 | E20: 售前咨询 | L20: {"event": "knowledge_search
A21: 46223.48 | B21: intent_classify | C21: 这件T恤是什么材质的 | D21: 这件T恤是什么材质的 | E21: 售前咨询 | L21: {"event": "answer_generate
A22: 46223.48 | B22: intent_classify | C22: 牛仔裤有弹力吗 | D22: 牛仔裤有弹力吗 | E22: 售前咨询 | L22: {"event": "answer_generate
A23: 46223.48 | B23: intent_classify | C23: 有优惠吗 | D23: 有优惠吗 | E23: 售前咨询 | F23: 0.95 | G23: 询问商品优惠信息 | H23: 无 | I23: 正常询问优惠 | J23: b0d3165b-8ba0-49ea-b4e0-afe42de8c241 | K23: 1
A24: 46223.48 | B24: intent_classify | C24: 有优惠吗 | D24: 有优惠吗 | E24: 售前咨询 | L24: {"event": "knowledge_search
A25: 46223.48 | B25: intent_classify | C25: 这个和那个有什么区别 | D25: 这个和那个有什么区别 | E25: 售前咨询 | F25: 0.95 | G25: 询问商品区别，属购买前信息咨询 | H25: 无 | I25: 普通询问差异 | J25: 5202b348-397c-49f7-929c-aaf5001769c5 | K25: 1
A26: 46223.48 | B26: intent_classify | C26: 有优惠吗 | D26: 有优惠吗 | E26: 售前咨询 | L26: {"event": "answer_generate
A27: 46223.48 | B27: intent_classify | C27: 这个和那个有什么区别 | D27: 这个和那个有什么区别 | E27: 售前咨询 | L27: {"event": "knowledge_search
A28: 46223.48 | B28: intent_classify | C28: 现在下单什么时候能到 | D28: 现在下单什么时候能到 | E28: 售前咨询 | F28: 0.98 | G28: 询问下单后的到货时间，属于购买前物流时效咨询 | H28: 无 | I28: 正常咨询物流时间 | J28: e75c2a8e-3f76-45ca-8189-ab3155a911eb | K28: 1
A29: 46223.48 | B29: intent_classify | C29: 现在下单什么时候能到 | D29: 现在下单什么时候能到 | E29: 售前咨询 | L29: {"event": "knowledge_search
A30: 46223.48 | B30: intent_classify | C30: 现在下单什么时候能到 | D30: 现在下单什么时候能到 | E30: 售前咨询 | L30: {"event": "answer_generate
A31: 46223.48 | B31: intent_classify | C31: 能便宜点吗 | D31: 能便宜点吗 | E31: 售前咨询 | F31: 0.99 | G31: 询问价格优惠，属于购买前咨询 | H31: 无 | I31: 正常砍价 | J31: 70b99fe9-1984-4d8c-9b90-8697b0ef08b9 | K31: 1
A32: 46223.48 | B32: intent_classify | C32: 能便宜点吗 | D32: 能便宜点吗 | E32: 售前咨询 | L32: {"event": "knowledge_search
A33: 46223.481 | B33: intent_classify | C33: 羽绒服适合什么温度穿 | D33: 羽绒服适合什么温度穿 | E33: 售前咨询 | F33: 0.95 | G33: 询问商品使用场景 | H33: 无 | I33: 正常商品咨询 | J33: e1272178-b1d8-40fb-93c3-30fe51a542f9 | K33: 1
A34: 46223.481 | B34: intent_classify | C34: 这件T恤是什么材质的 | D34: 这件T恤是什么材质的 | E34: 售前咨询 | F34: 0.98 | G34: 询问商品材质，属于购买前商品信息咨询 | H34: 无 | I34: 正常商品咨询 | J34: 029553eb-c3d6-4329-a135-a7d6b342e76c | K34: 1
A35: 46223.481 | B35: intent_classify | C35: 羽绒服适合什么温度穿 | D35: 羽绒服适合什么温度穿 | E35: 售前咨询 | L35: {"event": "knowledge_search
A36: 46223.481 | B36: intent_classify | C36: 这件T恤是什么材质的 | D36: 这件T恤是什么材质的 | E36: 售前咨询 | L36: {"event": "knowledge_search
A37: 46223.481 | B37: intent_classify | C37: 羽绒服适合什么温度穿 | D37: 羽绒服适合什么温度穿 | E37: 售前咨询 | L37: {"event": "answer_generate
A38: 46223.481 | B38: intent_classify | C38: 这件T恤是什么材质的 | D38: 这件T恤是什么材质的 | E38: 售前咨询 | L38: {"event": "answer_generate
A39: 46223.481 | B39: intent_classify | C39: 支持花呗吗 | D39: 支持花呗吗 | E39: 售前咨询 | F39: 0.95 | G39: 询问支付方式，属于购买前常见问题 | H39: 无 | I39: 普通询问，无风险 | J39: c209ef1e-8ddd-4a8c-865b-b77f61328a54 | K39: 1
A40: 46223.481 | B40: intent_classify | C40: 有优惠吗 | D40: 有优惠吗 | E40: 售前咨询 | F40: 0.99 | G40: 询问优惠，属于购买前的信息咨询 | H40: 无 | I40: 正常询问 | J40: d76385e1-ff08-401d-99e0-fa56854b0356 | K40: 1
...

Sheet 意图分析
A1: 意图 | B1: 次数 | C1: 占比
A2: {=UNIQUE('埋点数据'!E:E)} -> intent | B2: =COUNTIF('埋点数据'!E:E,A2) -> 1 | C2: =IF(B2>0,B2/SUM(B:B),0) -> 0.002617801
A3: 售前咨询 | B3: =COUNTIF('埋点数据'!E:E,A3) -> 145 | C3: =IF(B3>0,B3/SUM(B:B),0) -> 0.37958115
A4: 订单查询 | B4: =COUNTIF('埋点数据'!E:E,A4) -> 82 | C4: =IF(B4>0,B4/SUM(B:B),0) -> 0.21465969
A5: 其他 | B5: =COUNTIF('埋点数据'!E:E,A5) -> 21 | C5: =IF(B5>0,B5/SUM(B:B),0) -> 0.054973822
A6: 退换货 | B6: =COUNTIF('埋点数据'!E:E,A6) -> 38 | C6: =IF(B6>0,B6/SUM(B:B),0) -> 0.09947644
A7: 投诉 | B7: =COUNTIF('埋点数据'!E:E,A7) -> 34 | C7: =IF(B7>0,B7/SUM(B:B),0) -> 0.089005236
A8: 闲聊 | B8: =COUNTIF('埋点数据'!E:E,A8) -> 61 | C8: =IF(B8>0,B8/SUM(B:B),0) -> 0.15968586

Sheet 每日统计
A1: =IFERROR(__xludf.DUMMYFUNCTION("QUERY(ARRAYFORMULA({TEXT('埋点数据'!A2:A1000,""yyyy-mm-dd""),'埋点数据'!B2:B1000}),""select Col1,count(Col1) where Col1 is not null and Col1 <> '1899-12-30' group by Col1 label Col1'日期',count(Col1)'对话数'"",0)"),"日期") -> 日期 | B1: =IFERROR(__xludf.DUMMYFUNCTION("""COMPUTED_VALUE"""),"对话数") -> 对话数
A2: =IFERROR(__xludf.DUMMYFUNCTION("""COMPUTED_VALUE"""),"2026-07-13") -> 2026-07-13 | B2: =IFERROR(__xludf.DUMMYFUNCTION("""COMPUTED_VALUE"""),3.0) -> 3
A3: =IFERROR(__xludf.DUMMYFUNCTION("""COMPUTED_VALUE"""),"2026-07-20") -> 2026-07-20 | B3: =IFERROR(__xludf.DUMMYFUNCTION("""COMPUTED_VALUE"""),378.0) -> 378

Sheet 监控看板
A1: 总对话数 | B1: =COUNTA('埋点数据'!A:A)-1 -> 381
A2: 售前咨询数 | B2: =COUNTIF('埋点数据'!E:E, "售前咨询") -> 145
A3: 退换货数 | B3: =COUNTIF('埋点数据'!E:E, "退换货") -> 38
A4: 投诉数 | B4: =COUNTIF('埋点数据'!E:E, "投诉") -> 34
A5: 转人工数 | B5: =COUNTIF('埋点数据'!E:E, "投诉")+COUNTIF('埋点数据'!E:E, "其他") -> 55
A6: 风控拦截数 | B6: =COUNTIFS('埋点数据'!H:H, "<>", '埋点数据'!H:H, "<>无") -> 1
A7: 有知识回答率 | B7: =IFERROR(COUNTIF('埋点数据'!L:L, "*answer_generate*")/COUNTIF('埋点数据'!L:L, "*knowledge_search*"), 0) -> 0.63247863
